Traceback (most recent call last):
  File "<frozen importlib._bootstrap_external>", line 1346, in _path_importer_cache
KeyError: '/work/dlclarge2/masoodw-spino100/miniconda3/envs/spino/lib/python3.8/concurrent/futures'

During handling of the above exception, another exception occurred:

Traceback (most recent call last):
  File "<frozen importlib._bootstrap>", line 671, in _load_unlocked
  File "<frozen importlib._bootstrap_external>", line 843, in exec_module
  File "<frozen importlib._bootstrap>", line 219, in _call_with_frames_removed
  File "/work/dlclarge2/masoodw-spino100/miniconda3/envs/spino/lib/python3.8/site-packages/torch/__init__.py", line 1694, in <module>
    _C._initExtension(_manager_path())
  File "/work/dlclarge2/masoodw-spino100/miniconda3/envs/spino/lib/python3.8/site-packages/torch/cuda/__init__.py", line 31, in <module>
    from .graphs import (
  File "/work/dlclarge2/masoodw-spino100/miniconda3/envs/spino/lib/python3.8/site-packages/torch/cuda/graphs.py", line 6, in <module>
    from torch.utils import _pytree
  File "/work/dlclarge2/masoodw-spino100/miniconda3/envs/spino/lib/python3.8/site-packages/torch/utils/_pytree.py", line 260, in <module>
    def _register_pytree_node(
  File "/work/dlclarge2/masoodw-spino100/miniconda3/envs/spino/lib/python3.8/site-packages/typing_extensions.py", line 3246, in __call__
    import asyncio.coroutines
  File "/work/dlclarge2/masoodw-spino100/miniconda3/envs/spino/lib/python3.8/asyncio/__init__.py", line 8, in <module>
    from .base_events import *
  File "/work/dlclarge2/masoodw-spino100/miniconda3/envs/spino/lib/python3.8/asyncio/base_events.py", line 18, in <module>
    import concurrent.futures
  File "/work/dlclarge2/masoodw-spino100/miniconda3/envs/spino/lib/python3.8/concurrent/futures/__init__.py", line 8, in <module>
    from concurrent.futures._base import (FIRST_COMPLETED,
  File "<frozen importlib._bootstrap>", line 991, in _find_and_load
  File "<frozen importlib._bootstrap>", line 971, in _find_and_load_unlocked
  File "<frozen importlib._bootstrap>", line 914, in _find_spec
  File "<frozen importlib._bootstrap_external>", line 1407, in find_spec
  File "<frozen importlib._bootstrap_external>", line 1376, in _get_spec
  File "<frozen importlib._bootstrap_external>", line 1348, in _path_importer_cache
  File "<frozen importlib._bootstrap_external>", line 1324, in _path_hooks
  File "<frozen zipimport>", line 75, in __init__
  File "<frozen importlib._bootstrap_external>", line 142, in _path_stat
KeyboardInterrupt

During handling of the above exception, another exception occurred:

Traceback (most recent call last):
  File "panoptic_label_generator/boundary_fine_tuning.py", line 6, in <module>
    import torch
  File "<frozen importlib._bootstrap>", line 991, in _find_and_load
  File "<frozen importlib._bootstrap>", line 975, in _find_and_load_unlocked
  File "<frozen importlib._bootstrap>", line 671, in _load_unlocked
KeyboardInterrupt
